Workbook
Name mesice: 'Tabulka klientů 2023'!$N$300:$N$311
Name produkty: 'Tabulka klientů 2023'!$B$312:$B$319

Sheet Hlavní stránka
B1: Natalie Kruts | H1: Leden | I1: =MAX(T4:T294) -> 0 | T1: Pozice | U1: Únor | V1: =MAX(AG4:AG294) -> 0 | AG1: Pozice | AH1: Březen | AI1: =MAX(AT4:AT294) -> 0 | AT1: Pozice | AU1: Duben | AV1: =MAX(BG4:BG294) -> 0 | BG1: Pozice | BH1: Květen | BI1: =MAX(BT4:BT294) -> 0 | BT1: Pozice | BU1: Červen | BV1: =MAX(CG4:CG294) -> 0 | CG1: Pozice | CH1: Červenec | CI1: =MAX(CT4:CT294) -> 0 | CT1: Pozice | CU1: Srpen | CV1: =MAX(DG4:DG294) -> 0 | DG1: Pozice | DH1: Září | DI1: =MAX(DT4:DT294) -> 0 | DT1: Pozice | DU1: Říjen | DV1: =MAX(EG4:EG294) -> 0 | EG1: Pozice | EH1: Listopad | EI1: =MAX(ET4:ET294) -> 0 | ET1: Pozice | EU1: Prosinec | EV1: =MAX(FG4:FG294) -> 0 | FG1: Pozice
H2: ŽP | I2: In. S | J2: In. D | K2: Hypo | L2: Úvěr | M2: DPS | N2: POV, HAV | O2: NEM, DOM, ODP | P2: SS | Q2: TIP reality | R2: Ostatní | S2: max | T2: 0 | U2: ŽP | V2: In. S | W2: In. D | X2: Hypo | Y2: Úvěr | Z2: DPS | AA2: POV, HAV | AB2: NEM, DOM, ODP | AC2: SS | AD2: TIP reality | AE2: Ostatní | AF2: max | AG2: 0 | AH2: ŽP | AI2: In. S | AJ2: In. D | AK2: Hypo | AL2: Úvěr | AM2: DPS | AN2: POV, HAV | AO2: NEM, DOM, ODP | AP2: SS | AQ2: TIP reality | AR2: Ostatní | AS2: max | AT2: 0 | AU2: ŽP | AV2: In. S | AW2: In. D | AX2: Hypo | AY2: Úvěr | AZ2: DPS | BA2: POV, HAV | BB2: NEM, DOM, ODP | BC2: SS | BD2: TIP reality | BE2: Ostatní | BF2: max | BG2: 0 | BH2: ŽP | BI2: In. S | BJ2: In. D | BK2: Hypo | BL2: Úvěr | BM2: DPS | BN2: POV, HAV | BO2: NEM, DOM, ODP | BP2: SS | BQ2: TIP reality | BR2: Ostatní | BS2: max | BT2: 0 | BU2: ŽP | BV2: In. S | BW2: In. D | BX2: Hypo | BY2: Úvěr | BZ2: DPS | CA2: POV, HAV | CB2: NEM, DOM, ODP | CC2: SS | CD2: TIP reality | CE2: Ostatní | CF2: max | CG2: 0 | CH2: ŽP | CI2: In. S | CJ2: In. D | CK2: Hypo | CL2: Úvěr | CM2: DPS | CN2: POV, HAV | CO2: NEM, DOM, ODP | CP2: SS | CQ2: TIP reality | CR2: Ostatní | CS2: max | CT2: 0 | CU2: ŽP | CV2: In. S | CW2: In. D | CX2: Hypo | CY2: Úvěr | CZ2: DPS | DA2: POV, HAV | DB2: NEM, DOM, ODP | DC2: SS | DD2: TIP reality | DE2: Ostatní | DF2: max | DG2: 0 | DH2: ŽP | DI2: In. S | DJ2: In. D | DK2: Hypo | DL2: Úvěr | DM2: DPS | DN2: POV, HAV | DO2: NEM, DOM, ODP | DP2: SS | DQ2: TIP reality | DR2: Ostatní | DS2: max | DT2: 0 | DU2: ŽP | DV2: In. S | DW2: In. D | DX2: Hypo | DY2: Úvěr | DZ2: DPS | EA2: POV, HAV | EB2: NEM, DOM, ODP | EC2: SS | ED2: TIP reality | EE2: Ostatní | EF2: max | EG2: 0 | EH2: ŽP | EI2: In. S | EJ2: In. D | EK2: Hypo | EL2: Úvěr | EM2: DPS | EN2: POV, HAV | EO2: NEM, DOM, ODP | EP2: SS | EQ2: TIP reality | ER2: Ostatní | ES2: max | ET2: 0 | EU2: ŽP | EV2: In. S | EW2: In. D | EX2: Hypo | EY2: Úvěr | EZ2: DPS | FA2: POV, HAV | FB2: NEM, DOM, ODP | FC2: SS | FD2: TIP reality | FE2: Ostatní | FF2: max | FG2: 0
A4: Info o poradci (manželka, děti, nutný výdaje) | H4: =IF('Tabulka klientů 2023'!$R8='Hlavní stránka'!$H$1,1,0) -> 0 | I4: =IF('Tabulka klientů 2023'!$U8='Hlavní stránka'!$H$1,1,0) -> 0 | J4: =IF('Tabulka klientů 2023'!$X8='Hlavní stránka'!$H$1,1,0) -> 0 | K4: =IF('Tabulka klientů 2023'!$AA8='Hlavní stránka'!$H$1,1,0) -> 0 | L4: =IF('Tabulka klientů 2023'!$AD8='Hlavní stránka'!$H$1,1,0) -> 0 | M4: =IF('Tabulka klientů 2023'!$AG8='Hlavní stránka'!$H$1,1,0) -> 0 | N4: =IF('Tabulka klientů 2023'!$AJ8='Hlavní stránka'!$H$1,1,0) -> 0 | O4: =IF('Tabulka klientů 2023'!$AM8='Hlavní stránka'!$H$1,1,0) -> 0 | P4: =IF('Tabulka klientů 2023'!$AP8='Hlavní stránka'!$H$1,1,0) -> 0 | Q4: =IF('Tabulka klientů 2023'!$AS8='Hlavní stránka'!$H$1,1,0) -> 0 | R4: =IF('Tabulka klientů 2023'!$AV8='Hlavní stránka'!$H$1,1,0) -> 0 | S4: =MAX(H4:R4) -> 0 | T4: =T2+S4 -> 0 | U4: =IF('Tabulka klientů 2023'!$R8='Hlavní stránka'!U$1,1,0) -> 0 | V4: =IF('Tabulka klientů 2023'!$U8='Hlavní stránka'!U$1,1,0) -> 0 | W4: =IF('Tabulka klientů 2023'!$X8='Hlavní stránka'!U$1,1,0) -> 0 | X4: =IF('Tabulka klientů 2023'!$AA8='Hlavní stránka'!U$1,1,0) -> 0 | Y4: =IF('Tabulka klientů 2023'!$AD8='Hlavní stránka'!U$1,1,0) -> 0 | Z4: =IF('Tabulka klientů 2023'!$AG8='Hlavní stránka'!U$1,1,0) -> 0 | AA4: =IF('Tabulka klientů 2023'!$AJ8='Hlavní stránka'!U$1,1,0) -> 0 | AB4: =IF('Tabulka klientů 2023'!$AM8='Hlavní stránka'!U$1,1,0) -> 0 | AC4: =IF('Tabulka klientů 2023'!$AP8='Hlavní stránka'!U$1,1,0) -> 0 | AD4: =IF('Tabulka klientů 2023'!$AS8='Hlavní stránka'!U$1,1,0) -> 0 | AE4: =IF('Tabulka klientů 2023'!$AV8='Hlavní stránka'!U$1,1,0) -> 0 | AF4: =MAX(U4:AE4) -> 0 | AG4: =AG2+AF4 -> 0 | AH4: =IF('Tabulka klientů 2023'!$R8='Hlavní stránka'!AH$1,1,0) -> 0 | AI4: =IF('Tabulka klientů 2023'!$U8='Hlavní stránka'!AH$1,1,0) -> 0 | AJ4: =IF('Tabulka klientů 2023'!$X8='Hlavní stránka'!AH$1,1,0) -> 0 | AK4: =IF('Tabulka klientů 2023'!$AA8='Hlavní stránka'!AH$1,1,0) -> 0 | AL4: =IF('Tabulka klientů 2023'!$AD8='Hlavní stránka'!AH$1,1,0) -> 0 | AM4: =IF('Tabulka klientů 2023'!$AG8='Hlavní stránka'!AH$1,1,0) -> 0 | AN4: =IF('Tabulka klientů 2023'!$AJ8='Hlavní stránka'!AH$1,1,0) -> 0 | AO4: =IF('Tabulka klientů 2023'!$AM8='Hlavní stránka'!AH$1,1,0) -> 0 | AP4: =IF('Tabulka klientů 2023'!$AP8='Hlavní stránka'!AH$1,1,0) -> 0 | AQ4: =IF('Tabulka klientů 2023'!$AS8='Hlavní stránka'!AH$1,1,0) -> 0 | AR4: =IF('Tabulka klientů 2023'!$AV8='Hlavní stránka'!AH$1,1,0) -> 0 | AS4: =MAX(AH4:AR4) -> 0 | AT4: =AT2+AS4 -> 0 | AU4: =IF('Tabulka klientů 2023'!$R8='Hlavní stránka'!AU$1,1,0) -> 0 | AV4: =IF('Tabulka klientů 2023'!$U8='Hlavní stránka'!AU$1,1,0) -> 0 | AW4: =IF('Tabulka klientů 2023'!$X8='Hlavní stránka'!AU$1,1,0) -> 0 | AX4: =IF('Tabulka klientů 2023'!$AA8='Hlavní stránka'!AU$1,1,0) -> 0 | AY4: =IF('Tabulka klientů 2023'!$AD8='Hlavní stránka'!AU$1,1,0) -> 0 | AZ4: =IF('Tabulka klientů 2023'!$AG8='Hlavní stránka'!AU$1,1,0) -> 0 | BA4: =IF('Tabulka klientů 2023'!$AJ8='Hlavní stránka'!AU$1,1,0) -> 0 | BB4: =IF('Tabulka klientů 2023'!$AM8='Hlavní stránka'!AU$1,1,0) -> 0 | BC4: =IF('Tabulka klientů 2023'!$AP8='Hlavní stránka'!AU$1,1,0) -> 0 | BD4: =IF('Tabulka klientů 2023'!$AS8='Hlavní stránka'!AU$1,1,0) -> 0 | BE4: =IF('Tabulka klientů 2023'!$AV8='Hlavní stránka'!AU$1,1,0) -> 0 | BF4: =MAX(AU4:BE4) -> 0 | BG4: =BG2+BF4 -> 0 | BH4: =IF('Tabulka klientů 2023'!$R8='Hlavní stránka'!BH$1,1,0) -> 0 | BI4: =IF('Tabulka klientů 2023'!$U8='Hlavní stránka'!BH$1,1,0) -> 0 | BJ4: =IF('Tabulka klientů 2023'!$X8='Hlavní stránka'!BH$1,1,0) -> 0 | BK4: =IF('Tabulka klientů 2023'!$AA8='Hlavní stránka'!BH$1,1,0) -> 0 | BL4: =IF('Tabulka klientů 2023'!$AD8='Hlavní stránka'!BH$1,1,0) -> 0 | BM4: =IF('Tabulka klientů 2023'!$AG8='Hlavní stránka'!BH$1,1,0) -> 0 | BN4: =IF('Tabulka klientů 2023'!$AJ8='Hlavní stránka'!BH$1,1,0) -> 0 | BO4: =IF('Tabulka klientů 2023'!$AM8='Hlavní stránka'!BH$1,1,0) -> 0 | BP4: =IF('Tabulka klientů 2023'!$AP8='Hlavní stránka'!BH$1,1,0) -> 0 | BQ4: =IF('Tabulka klientů 2023'!$AS8='Hlavní stránka'!BH$1,1,0) -> 0 | BR4: =IF('Tabulka klientů 2023'!$AV8='Hlavní stránka'!BH$1,1,0) -> 0 | BS4: =MAX(BH4:BR4) -> 0 | BT4: =BT2+BS4 -> 0 | BU4: =IF('Tabulka klientů 2023'!$R8='Hlavní stránka'!BU$1,1,0) -> 0 | BV4: =IF('Tabulka klientů 2023'!$U8='Hlavní stránka'!BU$1,1,0) -> 0 | BW4: =IF('Tabulka klientů 2023'!$X8='Hlavní stránka'!BU$1,1,0) -> 0 | BX4: =IF('Tabulka klientů 2023'!$AA8='Hlavní stránka'!BU$1,1,0) -> 0 | BY4: =IF('Tabulka klientů 2023'!$AD8='Hlavní stránka'!BU$1,1,0) -> 0 | BZ4: =IF('Tabulka klientů 2023'!$AG8='Hlavní stránka'!BU$1,1,0) -> 0 | CA4: =IF('Tabulka klientů 2023'!$AJ8='Hlavní stránka'!BU$1,1,0) -> 0 | CB4: =IF('Tabulka klientů 2023'!$AM8='Hlavní stránka'!BU$1,1,0) -> 0 | CC4: =IF('Tabulka klientů 2023'!$AP8='Hlavní stránka'!BU$1,1,0) -> 0 | CD4: =IF('Tabulka klientů 2023'!$AS8='Hlavní stránka'!BU$1,1,0) -> 0 | CE4: =IF('Tabulka klientů 2023'!$AV8='Hlavní stránka'!BU$1,1,0) -> 0 | CF4: =MAX(BU4:CE4) -> 0 | CG4: =CG2+CF4 -> 0 | CH4: =IF('Tabulka klientů 2023'!$R8='Hlavní stránka'!CH$1,1,0) -> 0 | CI4: =IF('Tabulka klientů 2023'!$U8='Hlavní stránka'!CH$1,1,0) -> 0 | CJ4: =IF('Tabulka klientů 2023'!$X8='Hlavní stránka'!CH$1,1,0) -> 0 | CK4: =IF('Tabulka klientů 2023'!$AA8='Hlavní stránka'!CH$1,1,0) -> 0 | CL4: =IF('Tabulka klientů 2023'!$AD8='Hlavní stránka'!CH$1,1,0) -> 0 | CM4: =IF('Tabulka klientů 2023'!$AG8='Hlavní stránka'!CH$1,1,0) -> 0 | CN4: =IF('Tabulka klientů 2023'!$AJ8='Hlavní stránka'!CH$1,1,0) -> 0 | CO4: =IF('Tabulka klientů 2023'!$AM8='Hlavní stránka'!CH$1,1,0) -> 0 | CP4: =IF('Tabulka klientů 2023'!$AP8='Hlavní stránka'!CH$1,1,0) -> 0 | CQ4: =IF('Tabulka klientů 2023'!$AS8='Hlavní stránka'!CH$1,1,0) -> 0 | CR4: =IF('Tabulka klientů 2023'!$AV8='Hlavní stránka'!CH$1,1,0) -> 0 | CS4: =MAX(CH4:CR4) -> 0 | CT4: =CT2+CS4 -> 0 | CU4: =IF('Tabulka klientů 2023'!$R8='Hlavní stránka'!CU$1,1,0) -> 0 | CV4: =IF('Tabulka klientů 2023'!$U8='Hlavní stránka'!CU$1,1,0) -> 0 | CW4: =IF('Tabulka klientů 2023'!$X8='Hlavní stránka'!CU$1,1,0) -> 0 | CX4: =IF('Tabulka klientů 2023'!$AA8='Hlavní stránka'!CU$1,1,0) -> 0 | CY4: =IF('Tabulka klientů 2023'!$AD8='Hlavní stránka'!CU$1,1,0) -> 0 | CZ4: =IF('Tabulka klientů 2023'!$AG8='Hlavní stránka'!CU$1,1,0) -> 0 | DA4: =IF('Tabulka klientů 2023'!$AJ8='Hlavní stránka'!CU$1,1,0) -> 0 | DB4: =IF('Tabulka klientů 2023'!$AM8='Hlavní stránka'!CU$1,1,0) -> 0 | DC4: =IF('Tabulka klientů 2023'!$AP8='Hlavní stránka'!CU$1,1,0) -> 0 | DD4: =IF('Tabulka klientů 2023'!$AS8='Hlavní stránka'!CU$1,1,0) -> 0 | DE4: =IF('Tabulka klientů 2023'!$AV8='Hlavní stránka'!CU$1,1,0) -> 0 | DF4: =MAX(CU4:DE4) -> 0 | DG4: =DG2+DF4 -> 0 | DH4: =IF('Tabulka klientů 2023'!$R8='Hlavní stránka'!DH$1,1,0) -> 0 | DI4: =IF('Tabulka klientů 2023'!$U8='Hlavní stránka'!DH$1,1,0) -> 0 | DJ4: =IF('Tabulka klientů 2023'!$X8='Hlavní stránka'!DH$1,1,0) -> 0 | DK4: =IF('Tabulka klientů 2023'!$AA8='Hlavní stránka'!DH$1,1,0) -> 0 | DL4: =IF('Tabulka klientů 2023'!$AD8='Hlavní stránka'!DH$1,1,0) -> 0 | DM4: =IF('Tabulka klientů 2023'!$AG8='Hlavní stránka'!DH$1,1,0) -> 0 | DN4: =IF('Tabulka klientů 2023'!$AJ8='Hlavní stránka'!DH$1,1,0) -> 0 | DO4: =IF('Tabulka klientů 2023'!$AM8='Hlavní stránka'!DH$1,1,0) -> 0 | DP4: =IF('Tabulka klientů 2023'!$AP8='Hlavní stránka'!DH$1,1,0) -> 0 | DQ4: =IF('Tabulka klientů 2023'!$AS8='Hlavní stránka'!DH$1,1,0) -> 0 | DR4: =IF('Tabulka klientů 2023'!$AV8='Hlavní stránka'!DH$1,1,0) -> 0 | DS4: =MAX(DH4:DR4) -> 0 | DT4: =DT2+DS4 -> 0 | DU4: =IF('Tabulka klientů 2023'!$R8='Hlavní stránka'!DU$1,1,0) -> 0 | DV4: =IF('Tabulka klientů 2023'!$U8='Hlavní stránka'!DU$1,1,0) -> 0 | DW4: =IF('Tabulka klientů 2023'!$X8='Hlavní stránka'!DU$1,1,0) -> 0 | DX4: =IF('Tabulka klientů 2023'!$AA8='Hlavní stránka'!DU$1,1,0) -> 0 | DY4: =IF('Tabulka klientů 2023'!$AD8='Hlavní stránka'!DU$1,1,0) -> 0 | DZ4: =IF('Tabulka klientů 2023'!$AG8='Hlavní stránka'!DU$1,1,0) -> 0 | EA4: =IF('Tabulka klientů 2023'!$AJ8='Hlavní stránka'!DU$1,1,0) -> 0 | EB4: =IF('Tabulka klientů 2023'!$AM8='Hlavní stránka'!DU$1,1,0) -> 0 | EC4: =IF('Tabulka klientů 2023'!$AP8='Hlavní stránka'!DU$1,1,0) -> 0 | ED4: =IF('Tabulka klientů 2023'!$AS8='Hlavní stránka'!DU$1,1,0) -> 0 | EE4: =IF('Tabulka klientů 2023'!$AV8='Hlavní stránka'!DU$1,1,0) -> 0 | EF4: =MAX(DU4:EE4) -> 0 | EG4: =EG2+EF4 -> 0 | EH4: =IF('Tabulka klientů 2023'!$R8='Hlavní stránka'!EH$1,1,0) -> 0 | EI4: =IF('Tabulka klientů 2023'!$U8='Hlavní stránka'!EH$1,1,0) -> 0 | EJ4: =IF('Tabulka klientů 2023'!$X8='Hlavní stránka'!EH$1,1,0) -> 0 | EK4: =IF('Tabulka klientů 2023'!$AA8='Hlavní stránka'!EH$1,1,0) -> 0 | EL4: =IF('Tabulka klientů 2023'!$AD8='Hlavní stránka'!EH$1,1,0) -> 0 | EM4: =IF('Tabulka klientů 2023'!$AG8='Hlavní stránka'!EH$1,1,0) -> 0 | EN4: =IF('Tabulka klientů 2023'!$AJ8='Hlavní stránka'!EH$1,1,0) -> 0 | EO4: =IF('Tabulka klientů 2023'!$AM8='Hlavní stránka'!EH$1,1,0) -> 0 | EP4: =IF('Tabulka klientů 2023'!$AP8='Hlavní stránka'!EH$1,1,0) -> 0 | EQ4: =IF('Tabulka klientů 2023'!$AS8='Hlavní stránka'!EH$1,1,0) -> 0 | ER4: =IF('Tabulka klientů 2023'!$AV8='Hlavní stránka'!EH$1,1,0) -> 0 | ES4: =MAX(EH4:ER4) -> 0 | ET4: =ET2+ES4 -> 0 | EU4: =IF('Tabulka klientů 2023'!$R8='Hlavní stránka'!EU$1,1,0) -> 0 | EV4: =IF('Tabulka klientů 2023'!$U8='Hlavní stránka'!EU$1,1,0) -> 0 | EW4: =IF('Tabulka klientů 2023'!$X8='Hlavní stránka'!EU$1,1,0) -> 0 | EX4: =IF('Tabulka klientů 2023'!$AA8='Hlavní stránka'!EU$1,1,0) -> 0 | EY4: =IF('Tabulka klientů 2023'!$AD8='Hlavní stránka'!EU$1,1,0) -> 0 | EZ4: =IF('Tabulka klientů 2023'!$AG8='Hlavní stránka'!EU$1,1,0) -> 0 | FA4: =IF('Tabulka klientů 2023'!$AJ8='Hlavní stránka'!EU$1,1,0) -> 0 | FB4: =IF('Tabulka klientů 2023'!$AM8='Hlavní stránka'!EU$1,1,0) -> 0 | FC4: =IF('Tabulka klientů 2023'!$AP8='Hlavní stránka'!EU$1,1,0) -> 0 | FD4: =IF('Tabulka klientů 2023'!$AS8='Hlavní stránka'!EU$1,1,0) -> 0 | FE4: =IF('Tabulka klientů 2023'!$AV8='Hlavní stránka'!EU$1,1,0) -> 0 | FF4: =MAX(EU4:FE4) -> 0 | FG4: =FG2+FF4 -> 0
H5: =IF('Tabulka klientů 2023'!$R9='Hlavní stránka'!$H$1,1,0) -> 0 | I5: =IF('Tabulka klientů 2023'!$U9='Hlavní stránka'!$H$1,1,0) -> 0 | J5: =IF('Tabulka klientů 2023'!$X9='Hlavní stránka'!$H$1,1,0) -> 0 | K5: =IF('Tabulka klientů 2023'!$AA9='Hlavní stránka'!$H$1,1,0) -> 0 | L5: =IF('Tabulka klientů 2023'!$AD9='Hlavní stránka'!$H$1,1,0) -> 0 | M5: =IF('Tabulka klientů 2023'!$AG9='Hlavní stránka'!$H$1,1,0) -> 0 | N5: =IF('Tabulka klientů 2023'!$AJ9='Hlavní stránka'!$H$1,1,0) -> 0 | O5: =IF('Tabulka klientů 2023'!$AM9='Hlavní stránka'!$H$1,1,0) -> 0 | P5: =IF('Tabulka klientů 2023'!$AP9='Hlavní stránka'!$H$1,1,0) -> 0 | Q5: =IF('Tabulka klientů 2023'!$AS9='Hlavní stránka'!$H$1,1,0) -> 0 | R5: =IF('Tabulka klientů 2023'!$AV9='Hlavní stránka'!$H$1,1,0) -> 0 | S5: =MAX(H5:R5) -> 0 | T5: =T4+S4 -> 0 | U5: =IF('Tabulka klientů 2023'!$R9='Hlavní stránka'!U$1,1,0) -> 0 | V5: =IF('Tabulka klientů 2023'!$U9='Hlavní stránka'!U$1,1,0) -> 0 | W5: =IF('Tabulka klientů 2023'!$X9='Hlavní stránka'!U$1,1,0) -> 0 | X5: =IF('Tabulka klientů 2023'!$AA9='Hlavní stránka'!U$1,1,0) -> 0 | Y5: =IF('Tabulka klientů 2023'!$AD9='Hlavní stránka'!U$1,1,0) -> 0 | Z5: =IF('Tabulka klientů 2023'!$AG9='Hlavní stránka'!U$1,1,0) -> 0 | AA5: =IF('Tabulka klientů 2023'!$AJ9='Hlavní stránka'!U$1,1,0) -> 0 | AB5: =IF('Tabulka klientů 2023'!$AM9='Hlavní stránka'!U$1,1,0) -> 0 | AC5: =IF('Tabulka klientů 2023'!$AP9='Hlavní stránka'!U$1,1,0) -> 0 | AD5: =IF('Tabulka klientů 2023'!$AS9='Hlavní stránka'!U$1,1,0) -> 0 | AE5: =IF('Tabulka klientů 2023'!$AV9='Hlavní stránka'!U$1,1,0) -> 0 | AF5: =MAX(U5:AE5) -> 0 | AG5: =AG4+AF4 -> 0 | AH5: =IF('Tabulka klientů 2023'!$R9='Hlavní stránka'!AH$1,1,0) -> 0 | AI5: =IF('Tabulka klientů 2023'!$U9='Hlavní stránka'!AH$1,1,0) -> 0 | AJ5: =IF('Tabulka klientů 2023'!$X9='Hlavní stránka'!AH$1,1,0) -> 0 | AK5: =IF('Tabulka klientů 2023'!$AA9='Hlavní stránka'!AH$1,1,0) -> 0 | AL5: =IF('Tabulka klientů 2023'!$AD9='Hlavní stránka'!AH$1,1,0) -> 0 | AM5: =IF('Tabulka klientů 2023'!$AG9='Hlavní stránka'!AH$1,1,0) -> 0 | AN5: =IF('Tabulka klientů 2023'!$AJ9='Hlavní stránka'!AH$1,1,0) -> 0 | AO5: =IF('Tabulka klientů 2023'!$AM9='Hlavní stránka'!AH$1,1,0) -> 0 | AP5: =IF('Tabulka klientů 2023'!$AP9='Hlavní stránka'!AH$1,1,0) -> 0 | AQ5: =IF('Tabulka klientů 2023'!$AS9='Hlavní stránka'!AH$1,1,0) -> 0 | AR5: =IF('Tabulka klientů 2023'!$AV9='Hlavní stránka'!AH$1,1,0) -> 0 | AS5: =MAX(AH5:AR5) -> 0 | AT5: =AT4+AS4 -> 0 | AU5: =IF('Tabulka klientů 2023'!$R9='Hlavní stránka'!AU$1,1,0) -> 0 | AV5: =IF('Tabulka klientů 2023'!$U9='Hlavní stránka'!AU$1,1,0) -> 0 | AW5: =IF('Tabulka klientů 2023'!$X9='Hlavní stránka'!AU$1,1,0) -> 0 | AX5: =IF('Tabulka klientů 2023'!$AA9='Hlavní stránka'!AU$1,1,0) -> 0 | AY5: =IF('Tabulka klientů 2023'!$AD9='Hlavní stránka'!AU$1,1,0) -> 0 | AZ5: =IF('Tabulka klientů 2023'!$AG9='Hlavní stránka'!AU$1,1,0) -> 0 | BA5: =IF('Tabulka klientů 2023'!$AJ9='Hlavní stránka'!AU$1,1,0) -> 0 | BB5: =IF('Tabulka klientů 2023'!$AM9='Hlavní stránka'!AU$1,1,0) -> 0 | BC5: =IF('Tabulka klientů 2023'!$AP9='Hlavní stránka'!AU$1,1,0) -> 0 | BD5: =IF('Tabulka klientů 2023'!$AS9='Hlavní stránka'!AU$1,1,0) -> 0 | BE5: =IF('Tabulka klientů 2023'!$AV9='Hlavní stránka'!AU$1,1,0) -> 0 | BF5: =MAX(AU5:BE5) -> 0 | BG5: =BG4+BF4 -> 0 | BH5: =IF('Tabulka klientů 2023'!$R9='Hlavní stránka'!BH$1,1,0) -> 0 | BI5: =IF('Tabulka klientů 2023'!$U9='Hlavní stránka'!BH$1,1,0) -> 0 | BJ5: =IF('Tabulka klientů 2023'!$X9='Hlavní stránka'!BH$1,1,0) -> 0 | BK5: =IF('Tabulka klientů 2023'!$AA9='Hlavní stránka'!BH$1,1,0) -> 0 | BL5: =IF('Tabulka klientů 2023'!$AD9='Hlavní stránka'!BH$1,1,0) -> 0 | BM5: =IF('Tabulka klientů 2023'!$AG9='Hlavní stránka'!BH$1,1,0) -> 0 | BN5: =IF('Tabulka klientů 2023'!$AJ9='Hlavní stránka'!BH$1,1,0) -> 0 | BO5: =IF('Tabulka klientů 2023'!$AM9='Hlavní stránka'!BH$1,1,0) -> 0 | BP5: =IF('Tabulka klientů 2023'!$AP9='Hlavní stránka'!BH$1,1,0) -> 0 | BQ5: =IF('Tabulka klientů 2023'!$AS9='Hlavní stránka'!BH$1,1,0) -> 0 | BR5: =IF('Tabulka klientů 2023'!$AV9='Hlavní stránka'!BH$1,1,0) -> 0 | BS5: =MAX(BH5:BR5) -> 0 | BT5: =BT4+BS4 -> 0 | BU5: =IF('Tabulka klientů 2023'!$R9='Hlavní stránka'!BU$1,1,0) -> 0 | BV5: =IF('Tabulka klientů 2023'!$U9='Hlavní stránka'!BU$1,1,0) -> 0 | BW5: =IF('Tabulka klientů 2023'!$X9='Hlavní stránka'!BU$1,1,0) -> 0 | BX5: =IF('Tabulka klientů 2023'!$AA9='Hlavní stránka'!BU$1,1,0) -> 0 | BY5: =IF('Tabulka klientů 2023'!$AD9='Hlavní stránka'!BU$1,1,0) -> 0 | BZ5: =IF('Tabulka klientů 2023'!$AG9='Hlavní stránka'!BU$1,1,0) -> 0 | CA5: =IF('Tabulka klientů 2023'!$AJ9='Hlavní stránka'!BU$1,1,0) -> 0 | CB5: =IF('Tabulka klientů 2023'!$AM9='Hlavní stránka'!BU$1,1,0) -> 0 | CC5: =IF('Tabulka klientů 2023'!$AP9='Hlavní stránka'!BU$1,1,0) -> 0 | CD5: =IF('Tabulka klientů 2023'!$AS9='Hlavní stránka'!BU$1,1,0) -> 0 | CE5: =IF('Tabulka klientů 2023'!$AV9='Hlavní stránka'!BU$1,1,0) -> 0 | CF5: =MAX(BU5:CE5) -> 0 | CG5: =CG4+CF4 -> 0 | CH5: =IF('Tabulka klientů 2023'!$R9='Hlavní stránka'!CH$1,1,0) -> 0 | CI5: =IF('Tabulka klientů 2023'!$U9='Hlavní stránka'!CH$1,1,0) -> 0 | CJ5: =IF('Tabulka klientů 2023'!$X9='Hlavní stránka'!CH$1,1,0) -> 0 | CK5: =IF('Tabulka klientů 2023'!$AA9='Hlavní stránka'!CH$1,1,0) -> 0 | CL5: =IF('Tabulka klientů 2023'!$AD9='Hlavní stránka'!CH$1,1,0) -> 0 | CM5: =IF('Tabulka klientů 2023'!$AG9='Hlavní stránka'!CH$1,1,0) -> 0 | CN5: =IF('Tabulka klientů 2023'!$AJ9='Hlavní stránka'!CH$1,1,0) -> 0 | CO5: =IF('Tabulka klientů 2023'!$AM9='Hlavní stránka'!CH$1,1,0) -> 0 | CP5: =IF('Tabulka klientů 2023'!$AP9='Hlavní stránka'!CH$1,1,0) -> 0 | CQ5: =IF('Tabulka klientů 2023'!$AS9='Hlavní stránka'!CH$1,1,0) -> 0 | CR5: =IF('Tabulka klientů 2023'!$AV9='Hlavní stránka'!CH$1,1,0) -> 0 | CS5: =MAX(CH5:CR5) -> 0 | CT5: =CT4+CS4 -> 0 | CU5: =IF('Tabulka klientů 2023'!$R9='Hlavní stránka'!CU$1,1,0) -> 0 | CV5: =IF('Tabulka klientů 2023'!$U9='Hlavní stránka'!CU$1,1,0) -> 0 | CW5: =IF('Tabulka klientů 2023'!$X9='Hlavní stránka'!CU$1,1,0) -> 0 | CX5: =IF('Tabulka klientů 2023'!$AA9='Hlavní stránka'!CU$1,1,0) -> 0 | CY5: =IF('Tabulka klientů 2023'!$AD9='Hlavní stránka'!CU$1,1,0) -> 0 | CZ5: =IF('Tabulka klientů 2023'!$AG9='Hlavní stránka'!CU$1,1,0) -> 0 | DA5: =IF('Tabulka klientů 2023'!$AJ9='Hlavní stránka'!CU$1,1,0) -> 0 | DB5: =IF('Tabulka klientů 2023'!$AM9='Hlavní stránka'!CU$1,1,0) -> 0 | DC5: =IF('Tabulka klientů 2023'!$AP9='Hlavní stránka'!CU$1,1,0) -> 0 | DD5: =IF('Tabulka klientů 2023'!$AS9='Hlavní stránka'!CU$1,1,0) -> 0 | DE5: =IF('Tabulka klientů 2023'!$AV9='Hlavní stránka'!CU$1,1,0) -> 0 | DF5: =MAX(CU5:DE5) -> 0 | DG5: =DG4+DF4 -> 0 | DH5: =IF('Tabulka klientů 2023'!$R9='Hlavní stránka'!DH$1,1,0) -> 0 | DI5: =IF('Tabulka klientů 2023'!$U9='Hlavní stránka'!DH$1,1,0) -> 0 | DJ5: =IF('Tabulka klientů 2023'!$X9='Hlavní stránka'!DH$1,1,0) -> 0 | DK5: =IF('Tabulka klientů 2023'!$AA9='Hlavní stránka'!DH$1,1,0) -> 0 | DL5: =IF('Tabulka klientů 2023'!$AD9='Hlavní stránka'!DH$1,1,0) -> 0 | DM5: =IF('Tabulka klientů 2023'!$AG9='Hlavní stránka'!DH$1,1,0) -> 0 | DN5: =IF('Tabulka klientů 2023'!$AJ9='Hlavní stránka'!DH$1,1,0) -> 0 | DO5: =IF('Tabulka klientů 2023'!$AM9='Hlavní stránka'!DH$1,1,0) -> 0 | DP5: =IF('Tabulka klientů 2023'!$AP9='Hlavní stránka'!DH$1,1,0) -> 0 | DQ5: =IF('Tabulka klientů 2023'!$AS9='Hlavní stránka'!DH$1,1,0) -> 0 | DR5: =IF('Tabulka klientů 2023'!$AV9='Hlavní stránka'!DH$1,1,0) -> 0 | DS5: =MAX(DH5:DR5) -> 0 | DT5: =DT4+DS4 -> 0 | DU5: =IF('Tabulka klientů 2023'!$R9='Hlavní stránka'!DU$1,1,0) -> 0 | DV5: =IF('Tabulka klientů 2023'!$U9='Hlavní stránka'!DU$1,1,0) -> 0 | DW5: =IF('Tabulka klientů 2023'!$X9='Hlavní stránka'!DU$1,1,0) -> 0 | DX5: =IF('Tabulka klientů 2023'!$AA9='Hlavní stránka'!DU$1,1,0) -> 0 | DY5: =IF('Tabulka klientů 2023'!$AD9='Hlavní stránka'!DU$1,1,0) -> 0 | DZ5: =IF('Tabulka klientů 2023'!$AG9='Hlavní stránka'!DU$1,1,0) -> 0 | EA5: =IF('Tabulka klientů 2023'!$AJ9='Hlavní stránka'!DU$1,1,0) -> 0 | EB5: =IF('Tabulka klientů 2023'!$AM9='Hlavní stránka'!DU$1,1,0) -> 0 | EC5: =IF('Tabulka klientů 2023'!$AP9='Hlavní stránka'!DU$1,1,0) -> 0 | ED5: =IF('Tabulka klientů 2023'!$AS9='Hlavní stránka'!DU$1,1,0) -> 0 | EE5: =IF('Tabulka klientů 2023'!$AV9='Hlavní stránka'!DU$1,1,0) -> 0 | EF5: =MAX(DU5:EE5) -> 0 | EG5: =EG4+EF4 -> 0 | EH5: =IF('Tabulka klientů 2023'!$R9='Hlavní stránka'!EH$1,1,0) -> 0 | EI5: =IF('Tabulka klientů 2023'!$U9='Hlavní stránka'!EH$1,1,0) -> 0 | EJ5: =IF('Tabulka klientů 2023'!$X9='Hlavní stránka'!EH$1,1,0) -> 0 | EK5: =IF('Tabulka klientů 2023'!$AA9='Hlavní stránka'!EH$1,1,0) -> 0 | EL5: =IF('Tabulka klientů 2023'!$AD9='Hlavní stránka'!EH$1,1,0) -> 0 | EM5: =IF('Tabulka klientů 2023'!$AG9='Hlavní stránka'!EH$1,1,0) -> 0 | EN5: =IF('Tabulka klientů 2023'!$AJ9='Hlavní stránka'!EH$1,1,0) -> 0 | EO5: =IF('Tabulka klientů 2023'!$AM9='Hlavní stránka'!EH$1,1,0) -> 0 | EP5: =IF('Tabulka klientů 2023'!$AP9='Hlavní stránka'!EH$1,1,0) -> 0 | EQ5: =IF('Tabulka klientů 2023'!$AS9='Hlavní stránka'!EH$1,1,0) -> 0 | ER5: =IF('Tabulka klientů 2023'!$AV9='Hlavní stránka'!EH$1,1,0) -> 0 | ES5: =MAX(EH5:ER5) -> 0 | ET5: =ET4+ES4 -> 0 | EU5: =IF('Tabulka klientů 2023'!$R9='Hlavní stránka'!EU$1,1,0) -> 0 | EV5: =IF('Tabulka klientů 2023'!$U9='Hlavní stránka'!EU$1,1,0) -> 0 | EW5: =IF('Tabulka klientů 2023'!$X9='Hlavní stránka'!EU$1,1,0) -> 0 | EX5: =IF('Tabulka klientů 2023'!$AA9='Hlavní stránka'!EU$1,1,0) -> 0 | EY5: =IF('Tabulka klientů 2023'!$AD9='Hlavní stránka'!EU$1,1,0) -> 0 | EZ5: =IF('Tabulka klientů 2023'!$AG9='Hlavní stránka'!EU$1,1,0) -> 0 | FA5: =IF('Tabulka klientů 2023'!$AJ9='Hlavní stránka'!EU$1,1,0) -> 0 | FB5: =IF('Tabulka klientů 2023'!$AM9='Hlavní stránka'!EU$1,1,0) -> 0 | FC5: =IF('Tabulka klientů 2023'!$AP9='Hlavní stránka'!EU$1,1,0) -> 0 | FD5: =IF('Tabulka klientů 2023'!$AS9='Hlavní stránka'!EU$1,1,0) -> 0 | FE5: =IF('Tabulka klientů 2023'!$AV9='Hlavní stránka'!EU$1,1,0) -> 0 | FF5: =MAX(EU5:FE5) -> 0 | FG5: =FG4+FF4 -> 0
H6: =IF('Tabulka klientů 2023'!$R10='Hlavní stránka'!$H$1,1,0) -> 0 | I6: =IF('Tabulka klientů 2023'!$U10='Hlavní stránka'!$H$1,1,0) -> 0 | J6: =IF('Tabulka klientů 2023'!$X10='Hlavní stránka'!$H$1,1,0) -> 0 | K6: =IF('Tabulka klientů 2023'!$AA10='Hlavní stránka'!$H$1,1,0) -> 0 | L6: =IF('Tabulka klientů 2023'!$AD10='Hlavní stránka'!$H$1,1,0) -> 0 | M6: =IF('Tabulka klientů 2023'!$AG10='Hlavní stránka'!$H$1,1,0) -> 0 | N6: =IF('Tabulka klientů 2023'!$AJ10='Hlavní stránka'!$H$1,1,0) -> 0 | O6: =IF('Tabulka klientů 2023'!$AM10='Hlavní stránka'!$H$1,1,0) -> 0 | P6: =IF('Tabulka klientů 2023'!$AP10='Hlavní stránka'!$H$1,1,0) -> 0 | Q6: =IF('Tabulka klientů 2023'!$AS10='Hlavní stránka'!$H$1,1,0) -> 0 | R6: =IF('Tabulka klientů 2023'!$AV10='Hlavní stránka'!$H$1,1,0) -> 0 | S6: =MAX(H6:R6) -> 0 | T6: =T5+S5 -> 0 | U6: =IF('Tabulka klientů 2023'!$R10='Hlavní stránka'!U$1,1,0) -> 0 | V6: =IF('Tabulka klientů 2023'!$U10='Hlavní stránka'!U$1,1,0) -> 0 | W6: =IF('Tabulka klientů 2023'!$X10='Hlavní stránka'!U$1,1,0) -> 0 | X6: =IF('Tabulka klientů 2023'!$AA10='Hlavní stránka'!U$1,1,0) -> 0 | Y6: =IF('Tabulka klientů 2023'!$AD10='Hlavní stránka'!U$1,1,0) -> 0 | Z6: =IF('Tabulka klientů 2023'!$AG10='Hlavní stránka'!U$1,1,0) -> 0 | AA6: =IF('Tabulka klientů 2023'!$AJ10='Hlavní stránka'!U$1,1,0) -> 0 | AB6: =IF('Tabulka klientů 2023'!$AM10='Hlavní stránka'!U$1,1,0) -> 0 | AC6: =IF('Tabulka klientů 2023'!$AP10='Hlavní stránka'!U$1,1,0) -> 0 | AD6: =IF('Tabulka klientů 2023'!$AS10='Hlavní stránka'!U$1,1,0) -> 0 | AE6: =IF('Tabulka klientů 2023'!$AV10='Hlavní stránka'!U$1,1,0) -> 0 | AF6: =MAX(U6:AE6) -> 0 | AG6: =AG5+AF5 -> 0 | AH6: =IF('Tabulka klientů 2023'!$R10='Hlavní stránka'!AH$1,1,0) -> 0 | AI6: =IF('Tabulka klientů 2023'!$U10='Hlavní stránka'!AH$1,1,0) -> 0 | AJ6: =IF('Tabulka klientů 2023'!$X10='Hlavní stránka'!AH$1,1,0) -> 0 | AK6: =IF('Tabulka klientů 2023'!$AA10='Hlavní stránka'!AH$1,1,0) -> 0 | AL6: =IF('Tabulka klientů 2023'!$AD10='Hlavní stránka'!AH$1,1,0) -> 0 | AM6: =IF('Tabulka klientů 2023'!$AG10='Hlavní stránka'!AH$1,1,0) -> 0 | AN6: =IF('Tabulka klientů 2023'!$AJ10='Hlavní stránka'!AH$1,1,0) -> 0 | AO6: =IF('Tabulka klientů 2023'!$AM10='Hlavní stránka'!AH$1,1,0) -> 0 | AP6: =IF('Tabulka klientů 2023'!$AP10='Hlavní stránka'!AH$1,1,0) -> 0 | AQ6: =IF('Tabulka klientů 2023'!$AS10='Hlavní stránka'!AH$1,1,0) -> 0 | AR6: =IF('Tabulka klientů 2023'!$AV10='Hlavní stránka'!AH$1,1,0) -> 0 | AS6: =MAX(AH6:AR6) -> 0 | AT6: =AT5+AS5 -> 0 | AU6: =IF('Tabulka klientů 2023'!$R10='Hlavní stránka'!AU$1,1,0) -> 0 | AV6: =IF('Tabulka klientů 2023'!$U10='Hlavní stránka'!AU$1,1,0) -> 0 | AW6: =IF('Tabulka klientů 2023'!$X10='Hlavní stránka'!AU$1,1,0) -> 0 | AX6: =IF('Tabulka klientů 2023'!$AA10='Hlavní stránka'!AU$1,1,0) -> 0 | AY6: =IF('Tabulka klientů 2023'!$AD10='Hlavní stránka'!AU$1,1,0) -> 0 | AZ6: =IF('Tabulka klientů 2023'!$AG10='Hlavní stránka'!AU$1,1,0) -> 0 | BA6: =IF('Tabulka klientů 2023'!$AJ10='Hlavní stránka'!AU$1,1,0) -> 0 | BB6: =IF('Tabulka klientů 2023'!$AM10='Hlavní stránka'!AU$1,1,0) -> 0 | BC6: =IF('Tabulka klientů 2023'!$AP10='Hlavní stránka'!AU$1,1,0) -> 0 | BD6: =IF('Tabulka klientů 2023'!$AS10='Hlavní stránka'!AU$1,1,0) -> 0 | BE6: =IF('Tabulka klientů 2023'!$AV10='Hlavní stránka'!AU$1,1,0) -> 0 | BF6: =MAX(AU6:BE6) -> 0 | BG6: =BG5+BF5 -> 0 | BH6: =IF('Tabulka klientů 2023'!$R10='Hlavní stránka'!BH$1,1,0) -> 0 | BI6: =IF('Tabulka klientů 2023'!$U10='Hlavní stránka'!BH$1,1,0) -> 0 | BJ6: =IF('Tabulka klientů 2023'!$X10='Hlavní stránka'!BH$1,1,0) -> 0 | BK6: =IF('Tabulka klientů 2023'!$AA10='Hlavní stránka'!BH$1,1,0) -> 0 | BL6: =IF('Tabulka klientů 2023'!$AD10='Hlavní stránka'!BH$1,1,0) -> 0 | BM6: =IF('Tabulka klientů 2023'!$AG10='Hlavní stránka'!BH$1,1,0) -> 0 | BN6: =IF('Tabulka klientů 2023'!$AJ10='Hlavní stránka'!BH$1,1,0) -> 0 | BO6: =IF('Tabulka klientů 2023'!$AM10='Hlavní stránka'!BH$1,1,0) -> 0 | BP6: =IF('Tabulka klientů 2023'!$AP10='Hlavní stránka'!BH$1,1,0) -> 0 | BQ6: =IF('Tabulka klientů 2023'!$AS10='Hlavní stránka'!BH$1,1,0) -> 0 | BR6: =IF('Tabulka klientů 2023'!$AV10='Hlavní stránka'!BH$1,1,0) -> 0 | BS6: =MAX(BH6:BR6) -> 0 | BT6: =BT5+BS5 -> 0 | BU6: =IF('Tabulka klientů 2023'!$R10='Hlavní stránka'!BU$1,1,0) -> 0 | BV6: =IF('Tabulka klientů 2023'!$U10='Hlavní stránka'!BU$1,1,0) -> 0 | BW6: =IF('Tabulka klientů 2023'!$X10='Hlavní stránka'!BU$1,1,0) -> 0 | BX6: =IF('Tabulka klientů 2023'!$AA10='Hlavní stránka'!BU$1,1,0) -> 0 | BY6: =IF('Tabulka klientů 2023'!$AD10='Hlavní stránka'!BU$1,1,0) -> 0 | BZ6: =IF('Tabulka klientů 2023'!$AG10='Hlavní stránka'!BU$1,1,0) -> 0 | CA6: =IF('Tabulka klientů 2023'!$AJ10='Hlavní stránka'!BU$1,1,0) -> 0 | CB6: =IF('Tabulka klientů 2023'!$AM10='Hlavní stránka'!BU$1,1,0) -> 0 | CC6: =IF('Tabulka klientů 2023'!$AP10='Hlavní stránka'!BU$1,1,0) -> 0 | CD6: =IF('Tabulka klientů 2023'!$AS10='Hlavní stránka'!BU$1,1,0) -> 0 | CE6: =IF('Tabulka klientů 2023'!$AV10='Hlavní stránka'!BU$1,1,0) -> 0 | CF6: =MAX(BU6:CE6) -> 0 | CG6: =CG5+CF5 -> 0 | CH6: =IF('Tabulka klientů 2023'!$R10='Hlavní stránka'!CH$1,1,0) -> 0 | CI6: =IF('Tabulka klientů 2023'!$U10='Hlavní stránka'!CH$1,1,0) -> 0 | CJ6: =IF('Tabulka klientů 2023'!$X10='Hlavní stránka'!CH$1,1,0) -> 0 | CK6: =IF('Tabulka klientů 2023'!$AA10='Hlavní stránka'!CH$1,1,0) -> 0 | CL6: =IF('Tabulka klientů 2023'!$AD10='Hlavní stránka'!CH$1,1,0) -> 0 | CM6: =IF('Tabulka klientů 2023'!$AG10='Hlavní stránka'!CH$1,1,0) -> 0 | CN6: =IF('Tabulka klientů 2023'!$AJ10='Hlavní stránka'!CH$1,1,0) -> 0 | CO6: =IF('Tabulka klientů 2023'!$AM10='Hlavní stránka'!CH$1,1,0) -> 0 | CP6: =IF('Tabulka klientů 2023'!$AP10='Hlavní stránka'!CH$1,1,0) -> 0 | CQ6: =IF('Tabulka klientů 2023'!$AS10='Hlavní stránka'!CH$1,1,0) -> 0 | CR6: =IF('Tabulka klientů 2023'!$AV10='Hlavní stránka'!CH$1,1,0) -> 0 | CS6: =MAX(CH6:CR6) -> 0 | CT6: =CT5+CS5 -> 0 | CU6: =IF('Tabulka klientů 2023'!$R10='Hlavní stránka'!CU$1,1,0) -> 0 | CV6: =IF('Tabulka klientů 2023'!$U10='Hlavní stránka'!CU$1,1,0) -> 0 | CW6: =IF('Tabulka klientů 2023'!$X10='Hlavní stránka'!CU$1,1,0) -> 0 | CX6: =IF('Tabulka klientů 2023'!$AA10='Hlavní stránka'!CU$1,1,0) -> 0 | CY6: =IF('Tabulka klientů 2023'!$AD10='Hlavní stránka'!CU$1,1,0) -> 0 | CZ6: =IF('Tabulka klientů 2023'!$AG10='Hlavní stránka'!CU$1,1,0) -> 0 | DA6: =IF('Tabulka klientů 2023'!$AJ10='Hlavní stránka'!CU$1,1,0) -> 0 | DB6: =IF('Tabulka klientů 2023'!$AM10='Hlavní stránka'!CU$1,1,0) -> 0 | DC6: =IF('Tabulka klientů 2023'!$AP10='Hlavní stránka'!CU$1,1,0) -> 0 | DD6: =IF('Tabulka klientů 2023'!$AS10='Hlavní stránka'!CU$1,1,0) -> 0 | DE6: =IF('Tabulka klientů 2023'!$AV10='Hlavní stránka'!CU$1,1,0) -> 0 | DF6: =MAX(CU6:DE6) -> 0 | DG6: =DG5+DF5 -> 0 | DH6: =IF('Tabulka klientů 2023'!$R10='Hlavní stránka'!DH$1,1,0) -> 0 | DI6: =IF('Tabulka klientů 2023'!$U10='Hlavní stránka'!DH$1,1,0) -> 0 | DJ6: =IF('Tabulka klientů 2023'!$X10='Hlavní stránka'!DH$1,1,0) -> 0 | DK6: =IF('Tabulka klientů 2023'!$AA10='Hlavní stránka'!DH$1,1,0) -> 0 | DL6: =IF('Tabulka klientů 2023'!$AD10='Hlavní stránka'!DH$1,1,0) -> 0 | DM6: =IF('Tabulka klientů 2023'!$AG10='Hlavní stránka'!DH$1,1,0) -> 0 | DN6: =IF('Tabulka klientů 2023'!$AJ10='Hlavní stránka'!DH$1,1,0) -> 0 | DO6: =IF('Tabulka klientů 2023'!$AM10='Hlavní stránka'!DH$1,1,0) -> 0 | DP6: =IF('Tabulka klientů 2023'!$AP10='Hlavní stránka'!DH$1,1,0) -> 0 | DQ6: =IF('Tabulka klientů 2023'!$AS10='Hlavní stránka'!DH$1,1,0) -> 0 | DR6: =IF('Tabulka klientů 2023'!$AV10='Hlavní stránka'!DH$1,1,0) -> 0 | DS6: =MAX(DH6:DR6) -> 0 | DT6: =DT5+DS5 -> 0 | DU6: =IF('Tabulka klientů 2023'!$R10='Hlavní stránka'!DU$1,1,0) -> 0 | DV6: =IF('Tabulka klientů 2023'!$U10='Hlavní stránka'!DU$1,1,0) -> 0 | DW6: =IF('Tabulka klientů 2023'!$X10='Hlavní stránka'!DU$1,1,0) -> 0 | DX6: =IF('Tabulka klientů 2023'!$AA10='Hlavní stránka'!DU$1,1,0) -> 0 | DY6: =IF('Tabulka klientů 2023'!$AD10='Hlavní stránka'!DU$1,1,0) -> 0 | DZ6: =IF('Tabulka klientů 2023'!$AG10='Hlavní stránka'!DU$1,1,0) -> 0 | EA6: =IF('Tabulka klientů 2023'!$AJ10='Hlavní stránka'!DU$1,1,0) -> 0 | EB6: =IF('Tabulka klientů 2023'!$AM10='Hlavní stránka'!DU$1,1,0) -> 0 | EC6: =IF('Tabulka klientů 2023'!$AP10='Hlavní stránka'!DU$1,1,0) -> 0 | ED6: =IF('Tabulka klientů 2023'!$AS10='Hlavní stránka'!DU$1,1,0) -> 0 | EE6: =IF('Tabulka klientů 2023'!$AV10='Hlavní stránka'!DU$1,1,0) -> 0 | EF6: =MAX(DU6:EE6) -> 0 | EG6: =EG5+EF5 -> 0 | EH6: =IF('Tabulka klientů 2023'!$R10='Hlavní stránka'!EH$1,1,0) -> 0 | EI6: =IF('Tabulka klientů 2023'!$U10='Hlavní stránka'!EH$1,1,0) -> 0 | EJ6: =IF('Tabulka klientů 2023'!$X10='Hlavní stránka'!EH$1,1,0) -> 0 | EK6: =IF('Tabulka klientů 2023'!$AA10='Hlavní stránka'!EH$1,1,0) -> 0 | EL6: =IF('Tabulka klientů 2023'!$AD10='Hlavní stránka'!EH$1,1,0) -> 0 | EM6: =IF('Tabulka klientů 2023'!$AG10='Hlavní stránka'!EH$1,1,0) -> 0 | EN6: =IF('Tabulka klientů 2023'!$AJ10='Hlavní stránka'!EH$1,1,0) -> 0 | EO6: =IF('Tabulka klientů 2023'!$AM10='Hlavní stránka'!EH$1,1,0) -> 0 | EP6: =IF('Tabulka klientů 2023'!$AP10='Hlavní stránka'!EH$1,1,0) -> 0 | EQ6: =IF('Tabulka klientů 2023'!$AS10='Hlavní stránka'!EH$1,1,0) -> 0 | ER6: =IF('Tabulka klientů 2023'!$AV10='Hlavní stránka'!EH$1,1,0) -> 0 | ES6: =MAX(EH6:ER6) -> 0 | ET6: =ET5+ES5 -> 0 | EU6: =IF('Tabulka klientů 2023'!$R10='Hlavní stránka'!EU$1,1,0) -> 0 | EV6: =IF('Tabulka klientů 2023'!$U10='Hlavní stránka'!EU$1,1,0) -> 0 | EW6: =IF('Tabulka klientů 2023'!$X10='Hlavní stránka'!EU$1,1,0) -> 0 | EX6: =IF('Tabulka klientů 2023'!$AA10='Hlavní stránka'!EU$1,1,0) -> 0 | EY6: =IF('Tabulka klientů 2023'!$AD10='Hlavní stránka'!EU$1,1,0) -> 0 | EZ6: =IF('Tabulka klientů 2023'!$AG10='Hlavní stránka'!EU$1,1,0) -> 0 | FA6: =IF('Tabulka klientů 2023'!$AJ10='Hlavní stránka'!EU$1,1,0) -> 0 | FB6: =IF('Tabulka klientů 2023'!$AM10='Hlavní stránka'!EU$1,1,0) -> 0 | FC6: =IF('Tabulka klientů 2023'!$AP10='Hlavní stránka'!EU$1,1,0) -> 0 | FD6: =IF('Tabulka klientů 2023'!$AS10='Hlavní stránka'!EU$1,1,0) -> 0 | FE6: =IF('Tabulka klientů 2023'!$AV10='Hlavní stránka'!EU$1,1,0) -> 0 | FF6: =MAX(EU6:FE6) -> 0 | FG6: =FG5+FF5 -> 0
H7: =IF('Tabulka klientů 2023'!$R11='Hlavní stránka'!$H$1,1,0) -> 0 | I7: =IF('Tabulka klientů 2023'!$U11='Hlavní stránka'!$H$1,1,0) -> 0 | J7: =IF('Tabulka klientů 2023'!$X11='Hlavní stránka'!$H$1,1,0) -> 0 | K7: =IF('Tabulka klientů 2023'!$AA11='Hlavní stránka'!$H$1,1,0) -> 0 | L7: =IF('Tabulka klientů 2023'!$AD11='Hlavní stránka'!$H$1,1,0) -> 0 | M7: =IF('Tabulka klientů 2023'!$AG11='Hlavní stránka'!$H$1,1,0) -> 0 | N7: =IF('Tabulka klientů 2023'!$AJ11='Hlavní stránka'!$H$1,1,0) -> 0 | O7: =IF('Tabulka klientů 2023'!$AM11='Hlavní stránka'!$H$1,1,0) -> 0 | P7: =IF('Tabulka klientů 2023'!$AP11='Hlavní stránka'!$H$1,1,0) -> 0 | Q7: =IF('Tabulka klientů 2023'!$AS11='Hlavní stránka'!$H$1,1,0) -> 0 | R7: =IF('Tabulka klientů 2023'!$AV11='Hlavní stránka'!$H$1,1,0) -> 0 | S7: =MAX(H7:R7) -> 0 | T7: =T6+S6 -> 0 | U7: =IF('Tabulka klientů 2023'!$R11='Hlavní stránka'!U$1,1,0) -> 0 | V7: =IF('Tabulka klientů 2023'!$U11='Hlavní stránka'!U$1,1,0) -> 0 | W7: =IF('Tabulka klientů 2023'!$X11='Hlavní stránka'!U$1,1,0) -> 0 | X7: =IF('Tabulka klientů 2023'!$AA11='Hlavní stránka'!U$1,1,0) -> 0 | Y7: =IF('Tabulka klientů 2023'!$AD11='Hlavní stránka'!U$1,1,0) -> 0 | Z7: =IF('Tabulka klientů 2023'!$AG11='Hlavní stránka'!U$1,1,0) -> 0 | AA7: =IF('Tabulka klientů 2023'!$AJ11='Hlavní stránka'!U$1,1,0) -> 0 | AB7: =IF('Tabulka klientů 2023'!$AM11='Hlavní stránka'!U$1,1,0) -> 0 | AC7: =IF('Tabulka klientů 2023'!$AP11='Hlavní stránka'!U$1,1,0) -> 0 | AD7: =IF('Tabulka klientů 2023'!$AS11='Hlavní stránka'!U$1,1,0) -> 0 | AE7: =IF('Tabulka klientů 2023'!$AV11='Hlavní stránka'!U$1,1,0) -> 0 | AF7: =MAX(U7:AE7) -> 0 | AG7: =AG6+AF6 -> 0 | AH7: =IF('Tabulka klientů 2023'!$R11='Hlavní stránka'!AH$1,1,0) -> 0 | AI7: =IF('Tabulka klientů 2023'!$U11='Hlavní stránka'!AH$1,1,0) -> 0 | AJ7: =IF('Tabulka klientů 2023'!$X11='Hlavní stránka'!AH$1,1,0) -> 0 | AK7: =IF('Tabulka klientů 2023'!$AA11='Hlavní stránka'!AH$1,1,0) -> 0 | AL7: =IF('Tabulka klientů 2023'!$AD11='Hlavní stránka'!AH$1,1,0) -> 0 | AM7: =IF('Tabulka klientů 2023'!$AG11='Hlavní stránka'!AH$1,1,0) -> 0 | AN7: =IF('Tabulka klientů 2023'!$AJ11='Hlavní stránka'!AH$1,1,0) -> 0 | AO7: =IF('Tabulka klientů 2023'!$AM11='Hlavní stránka'!AH$1,1,0) -> 0 | AP7: =IF('Tabulka klientů 2023'!$AP11='Hlavní stránka'!AH$1,1,0) -> 0 | AQ7: =IF('Tabulka klientů 2023'!$AS11='Hlavní stránka'!AH$1,1,0) -> 0 | AR7: =IF('Tabulka klientů 2023'!$AV11='Hlavní stránka'!AH$1,1,0) -> 0 | AS7: =MAX(AH7:AR7) -> 0 | AT7: =AT6+AS6 -> 0 | AU7: =IF('Tabulka klientů 2023'!$R11='Hlavní stránka'!AU$1,1,0) -> 0 | AV7: =IF('Tabulka klientů 2023'!$U11='Hlavní stránka'!AU$1,1,0) -> 0 | AW7: =IF('Tabulka klientů 2023'!$X11='Hlavní stránka'!AU$1,1,0) -> 0 | AX7: =IF('Tabulka klientů 2023'!$AA11='Hlavní stránka'!AU$1,1,0) -> 0 | AY7: =IF('Tabulka klientů 2023'!$AD11='Hlavní stránka'!AU$1,1,0) -> 0 | AZ7: =IF('Tabulka klientů 2023'!$AG11='Hlavní stránka'!AU$1,1,0) -> 0 | BA7: =IF('Tabulka klientů 2023'!$AJ11='Hlavní stránka'!AU$1,1,0) -> 0 | BB7: =IF('Tabulka klientů 2023'!$AM11='Hlavní stránka'!AU$1,1,0) -> 0 | BC7: =IF('Tabulka klientů 2023'!$AP11='Hlavní stránka'!AU$1,1,0) -> 0 | BD7: =IF('Tabulka klientů 2023'!$AS11='Hlavní stránka'!AU$1,1,0) -> 0 | BE7: =IF('Tabulka klientů 2023'!$AV11='Hlavní stránka'!AU$1,1,0) -> 0 | BF7: =MAX(AU7:BE7) -> 0 | BG7: =BG6+BF6 -> 0 | BH7: =IF('Tabulka klientů 2023'!$R11='Hlavní stránka'!BH$1,1,0) -> 0 | BI7: =IF('Tabulka klientů 2023'!$U11='Hlavní stránka'!BH$1,1,0) -> 0 | BJ7: =IF('Tabulka klientů 2023'!$X11='Hlavní stránka'!BH$1,1,0) -> 0 | BK7: =IF('Tabulka klientů 2023'!$AA11='Hlavní stránka'!BH$1,1,0) -> 0 | BL7: =IF('Tabulka klientů 2023'!$AD11='Hlavní stránka'!BH$1,1,0) -> 0 | BM7: =IF('Tabulka klientů 2023'!$AG11='Hlavní stránka'!BH$1,1,0) -> 0 | BN7: =IF('Tabulka klientů 2023'!$AJ11='Hlavní stránka'!BH$1,1,0) -> 0 | BO7: =IF('Tabulka klientů 2023'!$AM11='Hlavní stránka'!BH$1,1,0) -> 0 | BP7: =IF('Tabulka klientů 2023'!$AP11='Hlavní stránka'!BH$1,1,0) -> 0 | BQ7: =IF('Tabulka klientů 2023'!$AS11='Hlavní stránka'!BH$1,1,0) -> 0 | BR7: =IF('Tabulka klientů 2023'!$AV11='Hlavní stránka'!BH$1,1,0) -> 0 | BS7: =MAX(BH7:BR7) -> 0 | BT7: =BT6+BS6 -> 0 | BU7: =IF('Tabulka klientů 2023'!$R11='Hlavní stránka'!BU$1,1,0) -> 0 | BV7: =IF('Tabulka klientů 2023'!$U11='Hlavní stránka'!BU$1,1,0) -> 0 | BW7: =IF('Tabulka klientů 2023'!$X11='Hlavní stránka'!BU$1,1,0) -> 0 | BX7: =IF('Tabulka klientů 2023'!$AA11='Hlavní stránka'!BU$1,1,0) -> 0 | BY7: =IF('Tabulka klientů 2023'!$AD11='Hlavní stránka'!BU$1,1,0) -> 0 | BZ7: =IF('Tabulka klientů 2023'!$AG11='Hlavní stránka'!BU$1,1,0) -> 0 | CA7: =IF('Tabulka klientů 2023'!$AJ11='Hlavní stránka'!BU$1,1,0) -> 0 | CB7: =IF('Tabulka klientů 2023'!$AM11='Hlavní stránka'!BU$1,1,0) -> 0 | CC7: =IF('Tabulka klientů 2023'!$AP11='Hlavní stránka'!BU$1,1,0) -> 0 | CD7: =IF('Tabulka klientů 2023'!$AS11='Hlavní stránka'!BU$1,1,0) -> 0 | CE7: =IF('Tabulka klientů 2023'!$AV11='Hlavní stránka'!BU$1,1,0) -> 0 | CF7: =MAX(BU7:CE7) -> 0 | CG7: =CG6+CF6 -> 0 | CH7: =IF('Tabulka klientů 2023'!$R11='Hlavní stránka'!CH$1,1,0) -> 0 | CI7: =IF('Tabulka klientů 2023'!$U11='Hlavní stránka'!CH$1,1,0) -> 0 | CJ7: =IF('Tabulka klientů 2023'!$X11='Hlavní stránka'!CH$1,1,0) -> 0 | CK7: =IF('Tabulka klientů 2023'!$AA11='Hlavní stránka'!CH$1,1,0) -> 0 | CL7: =IF('Tabulka klientů 2023'!$AD11='Hlavní stránka'!CH$1,1,0) -> 0 | CM7: =IF('Tabulka klientů 2023'!$AG11='Hlavní stránka'!CH$1,1,0) -> 0 | CN7: =IF('Tabulka klientů 2023'!$AJ11='Hlavní stránka'!CH$1,1,0) -> 0 | CO7: =IF('Tabulka klientů 2023'!$AM11='Hlavní stránka'!CH$1,1,0) -> 0 | CP7: =IF('Tabulka klientů 2023'!$AP11='Hlavní stránka'!CH$1,1,0) -> 0 | CQ7: =IF('Tabulka klientů 2023'!$AS11='Hlavní stránka'!CH$1,1,0) -> 0 | CR7: =IF('Tabulka klientů 2023'!$AV11='Hlavní stránka'!CH$1,1,0) -> 0 | CS7: =MAX(CH7:CR7) -> 0 | CT7: =CT6+CS6 -> 0 | CU7: =IF('Tabulka klientů 2023'!$R11='Hlavní stránka'!CU$1,1,0) -> 0 | CV7: =IF('Tabulka klientů 2023'!$U11='Hlavní stránka'!CU$1,1,0) -> 0 | CW7: =IF('Tabulka klientů 2023'!$X11='Hlavní stránka'!CU$1,1,0) -> 0 | CX7: =IF('Tabulka klientů 2023'!$AA11='Hlavní stránka'!CU$1,1,0) -> 0 | CY7: =IF('Tabulka klientů 2023'!$AD11='Hlavní stránka'!CU$1,1,0) -> 0 | CZ7: =IF('Tabulka klientů 2023'!$AG11='Hlavní stránka'!CU$1,1,0) -> 0 | DA7: =IF('Tabulka klientů 2023'!$AJ11='Hlavní stránka'!CU$1,1,0) -> 0 | DB7: =IF('Tabulka klientů 2023'!$AM11='Hlavní stránka'!CU$1,1,0) -> 0 | DC7: =IF('Tabulka klientů 2023'!$AP11='Hlavní stránka'!CU$1,1,0) -> 0 | DD7: =IF('Tabulka klientů 2023'!$AS11='Hlavní stránka'!CU$1,1,0) -> 0 | DE7: =IF('Tabulka klientů 2023'!$AV11='Hlavní stránka'!CU$1,1,0) -> 0 | DF7: =MAX(CU7:DE7) -> 0 | DG7: =DG6+DF6 -> 0 | DH7: =IF('Tabulka klientů 2023'!$R11='Hlavní stránka'!DH$1,1,0) -> 0 | DI7: =IF('Tabulka klientů 2023'!$U11='Hlavní stránka'!DH$1,1,0) -> 0 | DJ7: =IF('Tabulka klientů 2023'!$X11='Hlavní stránka'!DH$1,1,0) -> 0 | DK7: =IF('Tabulka klientů 2023'!$AA11='Hlavní stránka'!DH$1,1,0) -> 0 | DL7: =IF('Tabulka klientů 2023'!$AD11='Hlavní stránka'!DH$1,1,0) -> 0 | DM7: =IF('Tabulka klientů 2023'!$AG11='Hlavní stránka'!DH$1,1,0) -> 0 | DN7: =IF('Tabulka klientů 2023'!$AJ11='Hlavní stránka'!DH$1,1,0) -> 0 | DO7: =IF('Tabulka klientů 2023'!$AM11='Hlavní stránka'!DH$1,1,0) -> 0 | DP7: =IF('Tabulka klientů 2023'!$AP11='Hlavní stránka'!DH$1,1,0) -> 0 | DQ7: =IF('Tabulka klientů 2023'!$AS11='Hlavní stránka'!DH$1,1,0) -> 0 | DR7: =IF('Tabulka klientů 2023'!$AV11='Hlavní stránka'!DH$1,1,0) -> 0 | DS7: =MAX(DH7:DR7) -> 0 | DT7: =DT6+DS6 -> 0 | DU7: =IF('Tabulka klientů 2023'!$R11='Hlavní stránka'!DU$1,1,0) -> 0 | DV7: =IF('Tabulka klientů 2023'!$U11='Hlavní stránka'!DU$1,1,0) -> 0 | DW7: =IF('Tabulka klientů 2023'!$X11='Hlavní stránka'!DU$1,1,0) -> 0 | DX7: =IF('Tabulka klientů 2023'!$AA11='Hlavní stránka'!DU$1,1,0) -> 0 | DY7: =IF('Tabulka klientů 2023'!$AD11='Hlavní stránka'!DU$1,1,0) -> 0 | DZ7: =IF('Tabulka klientů 2023'!$AG11='Hlavní stránka'!DU$1,1,0) -> 0 | EA7: =IF('Tabulka klientů 2023'!$AJ11='Hlavní stránka'!DU$1,1,0) -> 0 | EB7: =IF('Tabulka klientů 2023'!$AM11='Hlavní stránka'!DU$1,1,0) -> 0 | EC7: =IF('Tabulka klientů 2023'!$AP11='Hlavní stránka'!DU$1,1,0) -> 0 | ED7: =IF('Tabulka klientů 2023'!$AS11='Hlavní stránka'!DU$1,1,0) -> 0 | EE7: =IF('Tabulka klientů 2023'!$AV11='Hlavní stránka'!DU$1,1,0) -> 0 | EF7: =MAX(DU7:EE7) -> 0 | EG7: =EG6+EF6 -> 0 | EH7: =IF('Tabulka klientů 2023'!$R11='Hlavní stránka'!EH$1,1,0) -> 0 | EI7: =IF('Tabulka klientů 2023'!$U11='Hlavní stránka'!EH$1,1,0) -> 0 | EJ7: =IF('Tabulka klientů 2023'!$X11='Hlavní stránka'!EH$1,1,0) -> 0 | EK7: =IF('Tabulka klientů 2023'!$AA11='Hlavní stránka'!EH$1,1,0) -> 0 | EL7: =IF('Tabulka klientů 2023'!$AD11='Hlavní stránka'!EH$1,1,0) -> 0 | EM7: =IF('Tabulka klientů 2023'!$AG11='Hlavní stránka'!EH$1,1,0) -> 0 | EN7: =IF('Tabulka klientů 2023'!$AJ11='Hlavní stránka'!EH$1,1,0) -> 0 | EO7: =IF('Tabulka klientů 2023'!$AM11='Hlavní stránka'!EH$1,1,0) -> 0 | EP7: =IF('Tabulka klientů 2023'!$AP11='Hlavní stránka'!EH$1,1,0) -> 0 | EQ7: =IF('Tabulka klientů 2023'!$AS11='Hlavní stránka'!EH$1,1,0) -> 0 | ER7: =IF('Tabulka klientů 2023'!$AV11='Hlavní stránka'!EH$1,1,0) -> 0 | ES7: =MAX(EH7:ER7) -> 0 | ET7: =ET6+ES6 -> 0 | EU7: =IF('Tabulka klientů 2023'!$R11='Hlavní stránka'!EU$1,1,0) -> 0 | EV7: =IF('Tabulka klientů 2023'!$U11='Hlavní stránka'!EU$1,1,0) -> 0 | EW7: =IF('Tabulka klientů 2023'!$X11='Hlavní stránka'!EU$1,1,0) -> 0 | EX7: =IF('Tabulka klientů 2023'!$AA11='Hlavní stránka'!EU$1,1,0) -> 0 | EY7: =IF('Tabulka klientů 2023'!$AD11='Hlavní stránka'!EU$1,1,0) -> 0 | EZ7: =IF('Tabulka klientů 2023'!$AG11='Hlavní stránka'!EU$1,1,0) -> 0 | FA7: =IF('Tabulka klientů 2023'!$AJ11='Hlavní stránka'!EU$1,1,0) -> 0 | FB7: =IF('Tabulka klientů 2023'!$AM11='Hlavní stránka'!EU$1,1,0) -> 0 | FC7: =IF('Tabulka klientů 2023'!$AP11='Hlavní stránka'!EU$1,1,0) -> 0 | FD7: =IF('Tabulka klientů 2023'!$AS11='Hlavní stránka'!EU$1,1,0) -> 0 | FE7: =IF('Tabulka klientů 2023'!$AV11='Hlavní stránka'!EU$1,1,0) -> 0 | FF7: =MAX(EU7:FE7) -> 0 | FG7: =FG6+FF6 -> 0
H8: =IF('Tabulka klientů 2023'!$R12='Hlavní stránka'!$H$1,1,0) -> 0 | I8: =IF('Tabulka klientů 2023'!$U12='Hlavní stránka'!$H$1,1,0) -> 0 | J8: =IF('Tabulka klientů 2023'!$X12='Hlavní stránka'!$H$1,1,0) -> 0 | K8: =IF('Tabulka klientů 2023'!$AA12='Hlavní stránka'!$H$1,1,0) -> 0 | L8: =IF('Tabulka klientů 2023'!$AD12='Hlavní stránka'!$H$1,1,0) -> 0 | M8: =IF('Tabulka klientů 2023'!$AG12='Hlavní stránka'!$H$1,1,0) -> 0 | N8: =IF('Tabulka klientů 2023'!$AJ12='Hlavní stránka'!$H$1,1,0) -> 0 | O8: =IF('Tabulka klientů 2023'!$AM12='Hlavní stránka'!$H$1,1,0) -> 0 | P8: =IF('Tabulka klientů 2023'!$AP12='Hlavní stránka'!$H$1,1,0) -> 0 | Q8: =IF('Tabulka klientů 2023'!$AS12='Hlavní stránka'!$H$1,1,0) -> 0 | R8: =IF('Tabulka klientů 2023'!$AV12='Hlavní stránka'!$H$1,1,0) -> 0 | S8: =MAX(H8:R8) -> 0 | T8: =T7+S7 -> 0 | U8: =IF('Tabulka klientů 2023'!$R12='Hlavní stránka'!U$1,1,0) -> 0 | V8: =IF('Tabulka klientů 2023'!$U12='Hlavní stránka'!U$1,1,0) -> 0 | W8: =IF('Tabulka klientů 2023'!$X12='Hlavní stránka'!U$1,1,0) -> 0 | X8: =IF('Tabulka klientů 2023'!$AA12='Hlavní stránka'!U$1,1,0) -> 0 | Y8: =IF('Tabulka klientů 2023'!$AD12='Hlavní stránka'!U$1,1,0) -> 0 | Z8: =IF('Tabulka klientů 2023'!$AG12='Hlavní stránka'!U$1,1,0) -> 0 | AA8: =IF('Tabulka klientů 2023'!$AJ12='Hlavní stránka'!U$1,1,0) -> 0 | AB8: =IF('Tabulka klientů 2023'!$AM12='Hlavní stránka'!U$1,1,0) -> 0 | AC8: =IF('Tabulka klientů 2023'!$AP12='Hlavní stránka'!U$1,1,0) -> 0 | AD8: =IF('Tabulka klientů 2023'!$AS12='Hlavní stránka'!U$1,1,0) -> 0 | AE8: =IF('Tabulka klientů 2023'!$AV12='Hlavní stránka'!U$1,1,0) -> 0 | AF8: =MAX(U8:AE8) -> 0 | AG8: =AG7+AF7 -> 0 | AH8: =IF('Tabulka klientů 2023'!$R12='Hlavní stránka'!AH$1,1,0) -> 0 | AI8: =IF('Tabulka klientů 2023'!$U12='Hlavní stránka'!AH$1,1,0) -> 0 | AJ8: =IF('Tabulka klientů 2023'!$X12='Hlavní stránka'!AH$1,1,0) -> 0 | AK8: =IF('Tabulka klientů 2023'!$AA12='Hlavní stránka'!AH$1,1,0) -> 0 | AL8: =IF('Tabulka klientů 2023'!$AD12='Hlavní stránka'!AH$1,1,0) -> 0 | AM8: =IF('Tabulka klientů 2023'!$AG12='Hlavní stránka'!AH$1,1,0) -> 0 | AN8: =IF('Tabulka klientů 2023'!$AJ12='Hlavní stránka'!AH$1,1,0) -> 0 | AO8: =IF('Tabulka klientů 2023'!$AM12='Hlavní stránka'!AH$1,1,0) -> 0 | AP8: =IF('Tabulka klientů 2023'!$AP12='Hlavní stránka'!AH$1,1,0) -> 0 | AQ8: =IF('Tabulka klientů 2023'!$AS12='Hlavní stránka'!AH$1,1,0) -> 0 | AR8: =IF('Tabulka klientů 2023'!$AV12='Hlavní stránka'!AH$1,1,0) -> 0 | AS8: =MAX(AH8:AR8) -> 0 | AT8: =AT7+AS7 -> 0 | AU8: =IF('Tabulka klientů 2023'!$R12='Hlavní stránka'!AU$1,1,0) -> 0 | AV8: =IF('Tabulka klientů 2023'!$U12='Hlavní stránka'!AU$1,1,0) -> 0 | AW8: =IF('Tabulka klientů 2023'!$X12='Hlavní stránka'!AU$1,1,0) -> 0 | AX8: =IF('Tabulka klientů 2023'!$AA12='Hlavní stránka'!AU$1,1,0) -> 0 | AY8: =IF('Tabulka klientů 2023'!$AD12='Hlavní stránka'!AU$1,1,0) -> 0 | AZ8: =IF('Tabulka klientů 2023'!$AG12='Hlavní stránka'!AU$1,1,0) -> 0 | BA8: =IF('Tabulka klientů 2023'!$AJ12='Hlavní stránka'!AU$1,1,0) -> 0 | BB8: =IF('Tabulka klientů 2023'!$AM12='Hlavní stránka'!AU$1,1,0) -> 0 | BC8: =IF('Tabulka klientů 2023'!$AP12='Hlavní stránka'!AU$1,1,0) -> 0 | BD8: =IF('Tabulka klientů 2023'!$AS12='Hlavní stránka'!AU$1,1,0) -> 0 | BE8: =IF('Tabulka klientů 2023'!$AV12='Hlavní stránka'!AU$1,1,0) -> 0 | BF8: =MAX(AU8:BE8) -> 0 | BG8: =BG7+BF7 -> 0 | BH8: =IF('Tabulka klientů 2023'!$R12='Hlavní stránka'!BH$1,1,0) -> 0 | BI8: =IF('Tabulka klientů 2023'!$U12='Hlavní stránka'!BH$1,1,0) -> 0 | BJ8: =IF('Tabulka klientů 2023'!$X12='Hlavní stránka'!BH$1,1,0) -> 0 | BK8: =IF('Tabulka klientů 2023'!$AA12='Hlavní stránka'!BH$1,1,0) -> 0 | BL8: =IF('Tabulka klientů 2023'!$AD12='Hlavní stránka'!BH$1,1,0) -> 0 | BM8: =IF('Tabulka klientů 2023'!$AG12='Hlavní stránka'!BH$1,1,0) -> 0 | BN8: =IF('Tabulka klientů 2023'!$AJ12='Hlavní stránka'!BH$1,1,0) -> 0 | BO8: =IF('Tabulka klientů 2023'!$AM12='Hlavní stránka'!BH$1,1,0) -> 0 | BP8: =IF('Tabulka klientů 2023'!$AP12='Hlavní stránka'!BH$1,1,0) -> 0 | BQ8: =IF('Tabulka klientů 2023'!$AS12='Hlavní stránka'!BH$1,1,0) -> 0 | BR8: =IF('Tabulka klientů 2023'!$AV12='Hlavní stránka'!BH$1,1,0) -> 0 | BS8: =MAX(BH8:BR8) -> 0 | BT8: =BT7+BS7 -> 0 | BU8: =IF('Tabulka klientů 2023'!$R12='Hlavní stránka'!BU$1,1,0) -> 0 | BV8: =IF('Tabulka klientů 2023'!$U12='Hlavní stránka'!BU$1,1,0) -> 0 | BW8: =IF('Tabulka klientů 2023'!$X12='Hlavní stránka'!BU$1,1,0) -> 0 | BX8: =IF('Tabulka klientů 2023'!$AA12='Hlavní stránka'!BU$1,1,0) -> 0 | BY8: =IF('Tabulka klientů 2023'!$AD12='Hlavní stránka'!BU$1,1,0) -> 0 | BZ8: =IF('Tabulka klientů 2023'!$AG12='Hlavní stránka'!BU$1,1,0) -> 0 | CA8: =IF('Tabulka klientů 2023'!$AJ12='Hlavní stránka'!BU$1,1,0) -> 0 | CB8: =IF('Tabulka klientů 2023'!$AM12='Hlavní stránka'!BU$1,1,0) -> 0 | CC8: =IF('Tabulka klientů 2023'!$AP12='Hlavní stránka'!BU$1,1,0) -> 0 | CD8: =IF('Tabulka klientů 2023'!$AS12='Hlavní stránka'!BU$1,1,0) -> 0 | CE8: =IF('Tabulka klientů 2023'!$AV12='Hlavní stránka'!BU$1,1,0) -> 0 | CF8: =MAX(BU8:CE8) -> 0 | CG8: =CG7+CF7 -> 0 | CH8: =IF('Tabulka klientů 2023'!$R12='Hlavní stránka'!CH$1,1,0) -> 0 | CI8: =IF('Tabulka klientů 2023'!$U12='Hlavní stránka'!CH$1,1,0) -> 0 | CJ8: =IF('Tabulka klientů 2023'!$X12='Hlavní stránka'!CH$1,1,0) -> 0 | CK8: =IF('Tabulka klientů 2023'!$AA12='Hlavní stránka'!CH$1,1,0) -> 0 | CL8: =IF('Tabulka klientů 2023'!$AD12='Hlavní stránka'!CH$1,1,0) -> 0 | CM8: =IF('Tabulka klientů 2023'!$AG12='Hlavní stránka'!CH$1,1,0) -> 0 | CN8: =IF('Tabulka klientů 2023'!$AJ12='Hlavní stránka'!CH$1,1,0) -> 0 | CO8: =IF('Tabulka klientů 2023'!$AM12='Hlavní stránka'!CH$1,1,0) -> 0 | CP8: =IF('Tabulka klientů 2023'!$AP12='Hlavní stránka'!CH$1,1,0) -> 0 | CQ8: =IF('Tabulka klientů 2023'!$AS12='Hlavní stránka'!CH$1,1,0) -> 0 | CR8: =IF('Tabulka klientů 2023'!$AV12='Hlavní stránka'!CH$1,1,0) -> 0 | CS8: =MAX(CH8:CR8) -> 0 | CT8: =CT7+CS7 -> 0 | CU8: =IF('Tabulka klientů 2023'!$R12='Hlavní stránka'!CU$1,1,0) -> 0 | CV8: =IF('Tabulka klientů 2023'!$U12='Hlavní stránka'!CU$1,1,0) -> 0 | CW8: =IF('Tabulka klientů 2023'!$X12='Hlavní stránka'!CU$1,1,0) -> 0 | CX8: =IF('Tabulka klientů 2023'!$AA12='Hlavní stránka'!CU$1,1,0) -> 0 | CY8: =IF('Tabulka klientů 2023'!$AD12='Hlavní stránka'!CU$1,1,0) -> 0 | CZ8: =IF('Tabulka klientů 2023'!$AG12='Hlavní stránka'!CU$1,1,0) -> 0 | DA8: =IF('Tabulka klientů 2023'!$AJ12='Hlavní stránka'!CU$1,1,0) -> 0 | DB8: =IF('Tabulka klientů 2023'!$AM12='Hlavní stránka'!CU$1,1,0) -> 0 | DC8: =IF('Tabulka klientů 2023'!$AP12='Hlavní stránka'!CU$1,1,0) -> 0 | DD8: =IF('Tabulka klientů 2023'!$AS12='Hlavní stránka'!CU$1,1,0) -> 0 | DE8: =IF('Tabulka klientů 2023'!$AV12='Hlavní stránka'!CU$1,1,0) -> 0 | DF8: =MAX(CU8:DE8) -> 0 | DG8: =DG7+DF7 -> 0 | DH8: =IF('Tabulka klientů 2023'!$R12='Hlavní stránka'!DH$1,1,0) -> 0 | DI8: =IF('Tabulka klientů 2023'!$U12='Hlavní stránka'!DH$1,1,0) -> 0 | DJ8: =IF('Tabulka klientů 2023'!$X12='Hlavní stránka'!DH$1,1,0) -> 0 | DK8: =IF('Tabulka klientů 2023'!$AA12='Hlavní stránka'!DH$1,1,0) -> 0 | DL8: =IF('Tabulka klientů 2023'!$AD12='Hlavní stránka'!DH$1,1,0) -> 0 | DM8: =IF('Tabulka klientů 2023'!$AG12='Hlavní stránka'!DH$1,1,0) -> 0 | DN8: =IF('Tabulka klientů 2023'!$AJ12='Hlavní stránka'!DH$1,1,0) -> 0 | DO8: =IF('Tabulka klientů 2023'!$AM12='Hlavní stránka'!DH$1,1,0) -> 0 | DP8: =IF('Tabulka klientů 2023'!$AP12='Hlavní stránka'!DH$1,1,0) -> 0 | DQ8: =IF('Tabulka klientů 2023'!$AS12='Hlavní stránka'!DH$1,1,0) -> 0 | DR8: =IF('Tabulka klientů 2023'!$AV12='Hlavní stránka'!DH$1,1,0) -> 0 | DS8: =MAX(DH8:DR8) -> 0 | DT8: =DT7+DS7 -> 0 | DU8: =IF('Tabulka klientů 2023'!$R12='Hlavní stránka'!DU$1,1,0) -> 0 | DV8: =IF('Tabulka klientů 2023'!$U12='Hlavní stránka'!DU$1,1,0) -> 0 | DW8: =IF('Tabulka klientů 2023'!$X12='Hlavní stránka'!DU$1,1,0) -> 0 | DX8: =IF('Tabulka klientů 2023'!$AA12='Hlavní stránka'!DU$1,1,0) -> 0 | DY8: =IF('Tabulka klientů 2023'!$AD12='Hlavní stránka'!DU$1,1,0) -> 0 | DZ8: =IF('Tabulka klientů 2023'!$AG12='Hlavní stránka'!DU$1,1,0) -> 0 | EA8: =IF('Tabulka klientů 2023'!$AJ12='Hlavní stránka'!DU$1,1,0) -> 0 | EB8: =IF('Tabulka klientů 2023'!$AM12='Hlavní stránka'!DU$1,1,0) -> 0 | EC8: =IF('Tabulka klientů 2023'!$AP12='Hlavní stránka'!DU$1,1,0) -> 0 | ED8: =IF('Tabulka klientů 2023'!$AS12='Hlavní stránka'!DU$1,1,0) -> 0 | EE8: =IF('Tabulka klientů 2023'!$AV12='Hlavní stránka'!DU$1,1,0) -> 0 | EF8: =MAX(DU8:EE8) -> 0 | EG8: =EG7+EF7 -> 0 | EH8: =IF('Tabulka klientů 2023'!$R12='Hlavní stránka'!EH$1,1,0) -> 0 | EI8: =IF('Tabulka klientů 2023'!$U12='Hlavní stránka'!EH$1,1,0) -> 0 | EJ8: =IF('Tabulka klientů 2023'!$X12='Hlavní stránka'!EH$1,1,0) -> 0 | EK8: =IF('Tabulka klientů 2023'!$AA12='Hlavní stránka'!EH$1,1,0) -> 0 | EL8: =IF('Tabulka klientů 2023'!$AD12='Hlavní stránka'!EH$1,1,0) -> 0 | EM8: =IF('Tabulka klientů 2023'!$AG12='Hlavní stránka'!EH$1,1,0) -> 0 | EN8: =IF('Tabulka klientů 2023'!$AJ12='Hlavní stránka'!EH$1,1,0) -> 0 | EO8: =IF('Tabulka klientů 2023'!$AM12='Hlavní stránka'!EH$1,1,0) -> 0 | EP8: =IF('Tabulka klientů 2023'!$AP12='Hlavní stránka'!EH$1,1,0) -> 0 | EQ8: =IF('Tabulka klientů 2023'!$AS12='Hlavní stránka'!EH$1,1,0) -> 0 | ER8: =IF('Tabulka klientů 2023'!$AV12='Hlavní stránka'!EH$1,1,0) -> 0 | ES8: =MAX(EH8:ER8) -> 0 | ET8: =ET7+ES7 -> 0 | EU8: =IF('Tabulka klientů 2023'!$R12='Hlavní stránka'!EU$1,1,0) -> 0 | EV8: =IF('Tabulka klientů 2023'!$U12='Hlavní stránka'!EU$1,1,0) -> 0 | EW8: =IF('Tabulka klientů 2023'!$X12='Hlavní stránka'!EU$1,1,0) -> 0 | EX8: =IF('Tabulka klientů 2023'!$AA12='Hlavní stránka'!EU$1,1,0) -> 0 | EY8: =IF('Tabulka klientů 2023'!$AD12='Hlavní stránka'!EU$1,1,0) -> 0 | EZ8: =IF('Tabulka klientů 2023'!$AG12='Hlavní stránka'!EU$1,1,0) -> 0 | FA8: =IF('Tabulka klientů 2023'!$AJ12='Hlavní stránka'!EU$1,1,0) -> 0 | FB8: =IF('Tabulka klientů 2023'!$AM12='Hlavní stránka'!EU$1,1,0) -> 0 | FC8: =IF('Tabulka klientů 2023'!$AP12='Hlavní stránka'!EU$1,1,0) -> 0 | FD8: =IF('Tabulka klientů 2023'!$AS12='Hlavní stránka'!EU$1,1,0) -> 0 | FE8: =IF('Tabulka klientů 2023'!$AV12='Hlavní stránka'!EU$1,1,0) -> 0 | FF8: =MAX(EU8:FE8) -> 0 | FG8: =FG7+FF7 -> 0
